<?xml version="1.0" encoding="UTF-8"?>
<robot xmlns:xacro="http://ros.org/wiki/xacro">
  
  <xacro:include filename="$(find boxbot_description)/urdf/common_materials.xacro" />

  <xacro:macro name="boxbot_head" params="parent *origin">
  
    <!-- links -->
    
    <link name="neck_base_link">
      <visual>
        <origin rpy="0 0 ${pi/2}" xyz="0 0 0"/>
        <geometry>
          <cylinder radius="0.02" length="0.02"/>
        </geometry>
        <xacro:material_black />
      </visual>
      <collision>
        <origin rpy="0 0 ${pi/2}" xyz="0 0 0"/>
        <geometry>
          <cylinder radius="0.02" length="0.02"/>
        </geometry>
      </collision>
      <inertial>
        <origin xyz="0.0 0.0 0.0" rpy="0 0 0" />
        <mass value="0.001" />
        <inertia ixx="0.001" ixy="0.0" ixz="0.0" iyy="0.001" iyz="0.0" izz="0.001" />
      </inertial>
    </link>
    
    <link name="pan_link">
      <visual>
        <origin rpy="0 0 ${pi/2}" xyz="0.02 0 0.017"/>
        <geometry>
          <box size="0.039 0.09 0.04"/> 
        </geometry>
        <xacro:material_black />
      </visual>
      <collision>
        <origin rpy="0 0 ${pi/2}" xyz="0 0 -0.0022"/>
        <geometry>
          <box size="0.039 0.09 0.04"/>
        </geometry>
      </collision>
      <inertial>
        <origin xyz="0.0 0.0 0.0" rpy="0 0 0" />
        <mass value="0.001" />
        <inertia ixx="0.001" ixy="0.0" ixz="0.0" iyy="0.001" iyz="0.0" izz="0.001" />
      </inertial>
    </link>
    
    <link name="tilt_link">
      <visual>
        <origin rpy="0 ${radians(-90)} 0" xyz="0.02 0 0"/>
        <geometry>
          <box size="0.02 0.1 0.005"/>
        </geometry>
        <xacro:material_black />
      </visual>
      <collision>
        <origin rpy="0 0 0" xyz="0 0 0"/>
        <geometry>
          <box size="0.02 0.1 0.005"/>
        </geometry>
      </collision>
      <inertial>
        <origin xyz="0.0 0.0 0.0" rpy="0 0 0" />
        <mass value="0.001" />
        <inertia ixx="0.001" ixy="0.0" ixz="0.0" iyy="0.001" iyz="0.0" izz="0.001" />
      </inertial>
    </link>
    
    <link name="left_camera_link">
      <visual>
        <origin rpy="0 0 0" xyz="0 0 0"/>
        <geometry>
          <cylinder radius="0.014" length="0.003"/>
        </geometry>
        <xacro:material_black />
      </visual>
      <collision>
        <origin rpy="0 0 0" xyz="0 0 0"/>
        <geometry>
          <cylinder radius="0.014" length="0.003"/>
        </geometry>
      </collision>
      <inertial>
        <origin xyz="0.0 0.0 0.0" rpy="0 0 0" />
        <mass value="0.001" />
        <inertia ixx="0.001" ixy="0.0" ixz="0.0" iyy="0.001" iyz="0.0" izz="0.001" />
      </inertial>
    </link>
    
    <link name="right_camera_link">
      <visual>
        <origin rpy="0 0 0" xyz="0 0 0"/>
        <geometry>
          <cylinder radius="0.014" length="0.003"/>
        </geometry>
        <xacro:material_black />
      </visual>
      <collision>
        <origin rpy="0 0 0" xyz="0 0 0"/>
        <geometry>
          <cylinder radius="0.014" length="0.003"/>
        </geometry>
      </collision>
      <inertial>
        <origin xyz="0.0 0.0 0.0" rpy="0 0 0" />
        <mass value="0.001" />
        <inertia ixx="0.001" ixy="0.0" ixz="0.0" iyy="0.001" iyz="0.0" izz="0.001" />
      </inertial>
    </link>
    
    <!-- joints -->
    
    <joint name="neck_base_joint" type="fixed">
      <xacro:insert_block name="origin" />
      <parent link="${parent}" />
      <child link="neck_base_link"/>
    </joint>
    
    <joint name="pan_joint" type="revolute">
      <axis xyz="0 0 1"/>
      <limit effort="3" lower="-3.14" upper="3.14" velocity="${pi}"/>
      <origin rpy="0 0 0" xyz="0 0 0.012"/>
      <parent link="neck_base_link"/>
      <child link="pan_link"/>
    </joint>

    <joint name="tilt_joint" type="revolute">
      <axis xyz="0 1 0"/>
      <limit effort="3" lower="${radians(-90)}" upper="0.50" velocity="${pi}"/>
      <origin rpy="0 0 0" xyz="0.055 0 0.025"/>
      <parent link="pan_link"/>
      <child link="tilt_link"/>
    </joint>
    
    <joint name="left_camera_joint" type="fixed">
      <origin rpy="0 ${radians(-90)} 0" xyz="0.023 0.045 0.005"/>
      <parent link="tilt_link" />
      <child link="left_camera_link"/>
    </joint>
    
    <joint name="right_camera_joint" type="fixed">
      <origin rpy="0 ${radians(-90)} 0" xyz="0.023 -0.045 0.005"/>
      <parent link="tilt_link" />
      <child link="right_camera_link"/>
    </joint>
    
 </xacro:macro>

</robot>
