<?xml version="1.0" encoding="UTF-8"?>
<robot xmlns:xacro="http://ros.org/wiki/xacro">
   <xacro:property name="M_SCALE" value="0.001"/>
   <xacro:property name="M_PI" value="3.14159"/>
   
   <xacro:include filename="$(find boxbot_description)/urdf/common_materials.xacro" />

   <xacro:macro name="widowx_arm" params="parent prefix *origin">

      <!-- links -->

      <link name="${prefix}arm_base_link">
         <inertial>
            <origin xyz="0.0 0.0 -0.04" rpy="0 0 0" />
            <mass value="0.001" />
            <inertia ixx="0.001" ixy="0.0" ixz="0.0" iyy="0.001" iyz="0.0" izz="0.001" />
         </inertial>
      </link>

      <link name="${prefix}shoulder_link">
         <visual>
            <origin xyz="0 0 0" rpy="0 0 0" />
            <geometry>
               <mesh filename="package://boxbot_description/meshes/shoulder_link.stl" />
            </geometry>
            <xacro:material_black />
         </visual>
         <collision>
            <origin xyz="0 0 0" rpy="0 0 0" />
            <geometry>
               <mesh filename="package://boxbot_description/meshes/shoulder_link.stl"/>
            </geometry>
         </collision>
         <inertial>
            <origin xyz="0.0 0.0 -0.04" rpy="0 0 0" />
            <mass value="0.061" />
            <inertia ixx="0.001" ixy="0.0" ixz="0.0" iyy="0.001" iyz="0.0" izz="0.001" />
         </inertial>
      </link>

      <link name="${prefix}biceps_link">
         <visual>
            <origin xyz="0 0 0" rpy="0 0 0" />
            <geometry>
               <mesh filename="package://boxbot_description/meshes/biceps_new_link.stl" />
            </geometry>
            <xacro:material_black />
         </visual>
         <collision>
            <origin xyz="0 0 0" rpy="0 0 0" />
            <geometry>
               <mesh filename="package://boxbot_description/meshes/biceps_new_link.stl" />
            </geometry>
         </collision>
         <inertial>
            <origin xyz="0.006670 0.0 0.083394" rpy="0 0 0" />
            <mass value="3.62e-1" />
            <inertia ixx="0.001" ixy="0.0" ixz="0.0" iyy="0.001" iyz="0.0" izz="0.001" />
         </inertial>
      </link>

      <link name="${prefix}forearm_1_link">
         <visual>
            <origin xyz="0 0 0" rpy="-${M_PI/2.0} 0 ${M_PI/2.0}" />
            <geometry>
               <mesh filename="package://boxbot_description/meshes/forearm_1_link.stl"/>
            </geometry>
           <xacro:material_black />
         </visual>
         <collision>
            <origin xyz="0 0 0" rpy="-${M_PI/2.0} 0 ${M_PI/2.0}" />
            <geometry>
               <mesh filename="package://boxbot_description/meshes/forearm_1_link.stl"/>
            </geometry>
         </collision>
         <inertial>
            <origin xyz="0 0 0" rpy="0 0 0" />
            <mass value="1.87e-1" />
            <inertia ixx="0.001" ixy="0.0" ixz="0.0" iyy="0.001" iyz="0.0" izz="0.001" />
         </inertial>
      </link>

      <link name="${prefix}forearm_2_link">
         <visual>
            <origin xyz="0 0 0" rpy="0 ${M_PI/2.0} 0" />
            <geometry>
               <mesh filename="package://boxbot_description/meshes/forearm_2_link.stl"/>
            </geometry>
           <xacro:material_black />
         </visual>
         <collision>
            <origin xyz="0 0 0" rpy="0 ${M_PI/2.0} 0" />
            <geometry>
               <mesh filename="package://boxbot_description/meshes/forearm_2_link.stl"/>
            </geometry>
         </collision>
         <inertial>
            <origin xyz="0.000018 0.0 0.090995" rpy="0 0 0" />
            <mass value="1.87e-1" />
            <inertia ixx="0.001" ixy="0.0" ixz="0.0" iyy="0.001" iyz="0.0" izz="0.001" />
         </inertial>
      </link>

      <link name="${prefix}wrist_1_link">
         <visual>
            <origin xyz="0 0 0" rpy="0 0 0" />
            <geometry>
               <mesh filename="package://boxbot_description/meshes/wrist_1_link.stl"/>
            </geometry>
            <xacro:material_black />
         </visual>
         <collision>
            <origin xyz="0 0 0" rpy="0 0 0" />
            <geometry>
               <mesh filename="package://boxbot_description/meshes/wrist_1_link.stl"/>
            </geometry>
         </collision>
         <inertial>
            <origin xyz="-0.010852 0.0 0.048078" rpy="0 0 0" />
            <mass value="9.1e-2" />
            <inertia ixx="0.001" ixy="0.0" ixz="0.0" iyy="0.001" iyz="0.0" izz="0.001" />
         </inertial>
      </link>

      <link name="${prefix}wrist_2_link">
         <visual>
            <origin xyz="0 0 0" rpy="0 0 0" />
            <geometry>
               <mesh filename="package://boxbot_description/meshes/wrist_2_link.new.stl"/>
            </geometry>
            <xacro:material_black />
         </visual>
         <collision>
            <origin xyz="0 0 0" rpy="0 0 0" />
            <geometry>
               <mesh filename="package://boxbot_description/meshes/wrist_2_link.new.stl"/>
            </geometry>
         </collision>
         <inertial>
            <origin xyz="-0.018000 0.0 0.01500 " rpy="0 0 0" />
            <mass value="6.3e-2" />
            <inertia ixx="0.001" ixy="0.0" ixz="0.0" iyy="0.001" iyz="0.0" izz="0.001" />
         </inertial>
      </link>


      <!-- joints -->

      <joint name="${prefix}arm_base_joint" type="fixed">
         <xacro:insert_block name="origin" />
         <parent link="${parent}" />
         <child link="${prefix}arm_base_link"/>
      </joint>

      <joint name="${prefix}shoulder_1_joint" type="revolute">
         <origin xyz="0 0 0" rpy="0 0 0" />
         <parent link="${prefix}arm_base_link" />
         <child link="${prefix}shoulder_link" />
         <axis xyz="0 0 1" />
         <limit lower="-2.617" upper="2.617" effort="6" velocity="0.785" />
      </joint>

      <joint name="${prefix}shoulder_2_joint" type="revolute">
         <origin xyz="0 0 0" rpy="0 0 ${M_PI}" />
         <parent link="${prefix}shoulder_link" />
         <child link="${prefix}biceps_link" />
         <axis xyz="0 1 0" />
         <limit lower="-1.571" upper="1.571" effort="6" velocity="1.571" />
      </joint>

      <joint name="${prefix}elbow_joint" type="revolute">
         <origin xyz="-${M_SCALE*48.25} 0 ${M_SCALE*141.8}" rpy="0 ${M_PI/2.0} ${M_PI}" />
         <parent link="${prefix}biceps_link" />
         <child link="${prefix}forearm_1_link" />
         <axis xyz="0 -1 0" />
         <limit lower="-1.571" upper="1.571" effort="6" velocity="1.571" />
      </joint>

      <joint name="${prefix}wrist_1_joint" type="revolute">
         <origin xyz="0 0 ${M_SCALE*92.8}" rpy="0 0 -${M_PI/2.0}" />
         <parent link="${prefix}forearm_1_link" />
         <child link="${prefix}forearm_2_link" />
         <axis xyz="0 0 1" />
         <limit lower="-2.617" upper="2.617" effort="2.5" velocity="1.571" />
      </joint>

      <joint name="${prefix}wrist_2_joint" type="revolute">
         <origin xyz="0 0 0.048" rpy="0 0 ${M_PI/2.0}" />
         <parent link="${prefix}forearm_2_link" />
         <child link="${prefix}wrist_1_link" />
         <axis xyz="0 1 0" />
         <limit lower="-1.745" upper="1.745" effort="2.5" velocity="1.571" />
      </joint>

      <joint name="${prefix}wrist_3_joint" type="revolute">
         <origin xyz="0 0 ${M_SCALE*71.5}" rpy="0 0 0" />
         <parent link="${prefix}wrist_1_link" />
         <child link="${prefix}wrist_2_link" />
         <axis xyz="0 0 1" />
         <limit lower="-2.617" upper="2.617" effort="1.5" velocity="1.571" />
      </joint>

      <!-- gripper -->
      <xacro:include filename="$(find boxbot_description)/urdf/widowx_gripper.xacro"/>

   </xacro:macro>

</robot>
