<?xml version="1.0" encoding="utf-8"?>
<!-- =================================================================================== -->
<!-- |    This document was autogenerated by xacro from boxbot.urdf.xacro              | -->
<!-- |    EDITING THIS FILE BY HAND IS NOT RECOMMENDED                                 | -->
<!-- =================================================================================== -->
<robot name="boxbot">
  <link name="world"/>
  <link name="base_link">
    <visual>
      <geometry>
        <box size="0.3048 0.3048 0.01905"/>
      </geometry>
      <material name="">
        <color rgba="0.96 0.76 0.13 1.0"/>
      </material>
    </visual>
    <!--Can't get collision to work for this link; likely a collision issue with the torso.-->
    <inertial>
      <!--placeholders-->
      <origin rpy="0 0 0" xyz="0.0 0.0 0.0"/>
      <mass value="1"/>
      <inertia ixx="1.0" ixy="0.0" ixz="0.0" iyy="1.0" iyz="0.0" izz="1.0"/>
    </inertial>
  </link>
  <link name="torso">
    <visual>
      <geometry>
        <box size="0.19685 0.12065 0.3556"/>
      </geometry>
      <material name="">
        <color rgba="0.96 0.76 0.13 1.0"/>
      </material>
    </visual>
    <collision>
      <geometry>
        <box size="0.19685 0.12065 0.3556"/>
      </geometry>
    </collision>
    <inertial>
      <!--placeholders-->
      <origin rpy="0 0 0" xyz="0.0 0.0 0.0"/>
      <mass value="1"/>
      <inertia ixx="1.0" ixy="0.0" ixz="0.0" iyy="1.0" iyz="0.0" izz="1.0"/>
    </inertial>
  </link>
  <joint name="fixed" type="fixed">
    <origin rpy="0 0 0" xyz="0 0 0.009525"/>
    <parent link="world"/>
    <child link="base_link"/>
  </joint>
  <joint name="waist_joint" type="fixed">
    <origin rpy="0 0 0" xyz="0 0 0.187325"/>
    <parent link="base_link"/>
    <child link="torso"/>
  </joint>
  <!-- links -->
  <link name="left_arm_base_link">
    <visual>
      <origin rpy="0 0 0" xyz="0 0 0"/>
      <geometry>
        <cylinder length="0.055" radius=".072"/>
      </geometry>
      <material name="">
        <color rgba="0.15 0.15 0.15 1.0"/>
      </material>
    </visual>
    <collision>
      <origin rpy="0 0 0" xyz="0 0 0"/>
      <geometry>
        <cylinder length="0.055" radius=".072"/>
      </geometry>
    </collision>
    <inertial>
      <origin rpy="0 0 0" xyz="0 0 0.0275"/>
      <mass value="1"/>
      <inertia ixx="1.0" ixy="0.0" ixz="0.0" iyy="1.0" iyz="0.0" izz="1.0"/>
    </inertial>
  </link>
  <link name="left_shoulder_link">
    <visual>
      <origin rpy="0 0 0" xyz="0 0 0"/>
      <geometry>
        <mesh filename="package://boxbot_description/meshes/shoulder_link.stl"/>
      </geometry>
      <material name="">
        <color rgba="0.15 0.15 0.15 1.0"/>
      </material>
    </visual>
    <collision>
      <origin rpy="0 0 0" xyz="0 0 0"/>
      <geometry>
        <mesh filename="package://boxbot_description/meshes/shoulder_link.stl"/>
      </geometry>
    </collision>
    <inertial>
      <origin rpy="0 0 0" xyz="0.0 0.0 -0.04"/>
      <mass value="0.061"/>
      <inertia ixx="0.001" ixy="0.0" ixz="0.0" iyy="0.001" iyz="0.0" izz="0.001"/>
    </inertial>
  </link>
  <link name="left_biceps_link">
    <visual>
      <origin rpy="0 0 0" xyz="0 0 0"/>
      <geometry>
        <mesh filename="package://boxbot_description/meshes/biceps_link.new.stl"/>
      </geometry>
      <material name="">
        <color rgba="0.15 0.15 0.15 1.0"/>
      </material>
    </visual>
    <collision>
      <origin rpy="0 0 0" xyz="0 0 0"/>
      <geometry>
        <mesh filename="package://boxbot_description/meshes/biceps_link.new.stl"/>
      </geometry>
    </collision>
    <inertial>
      <origin rpy="0 0 0" xyz="0.006670 0.0 0.083394"/>
      <mass value="3.62e-1"/>
      <inertia ixx="0.001" ixy="0.0" ixz="0.0" iyy="0.001" iyz="0.0" izz="0.001"/>
    </inertial>
  </link>
  <link name="left_forearm_link">
    <visual>
      <origin rpy="0 0 0" xyz="0 0 0"/>
      <geometry>
        <mesh filename="package://boxbot_description/meshes/forearm_link.new.stl"/>
      </geometry>
      <material name="">
        <color rgba="0.15 0.15 0.15 1.0"/>
      </material>
    </visual>
    <collision>
      <origin rpy="0 0 0" xyz="0 0 0"/>
      <geometry>
        <mesh filename="package://boxbot_description/meshes/forearm_link.new.stl"/>
      </geometry>
    </collision>
    <inertial>
      <origin rpy="0 0 0" xyz="0.000018 0.0 0.090995"/>
      <mass value="1.87e-1"/>
      <inertia ixx="0.001" ixy="0.0" ixz="0.0" iyy="0.001" iyz="0.0" izz="0.001"/>
    </inertial>
  </link>
  <link name="left_wrist_1_link">
    <visual>
      <origin rpy="0 0 0" xyz="0 0 0"/>
      <geometry>
        <mesh filename="package://boxbot_description/meshes/wrist_1_link.stl"/>
      </geometry>
      <material name="">
        <color rgba="0.15 0.15 0.15 1.0"/>
      </material>
    </visual>
    <collision>
      <origin rpy="0 0 0" xyz="0 0 0"/>
      <geometry>
        <mesh filename="package://boxbot_description/meshes/wrist_1_link.stl"/>
      </geometry>
    </collision>
    <inertial>
      <origin rpy="0 0 0" xyz="-0.010852 0.0 0.048078"/>
      <mass value="9.1e-2"/>
      <inertia ixx="0.001" ixy="0.0" ixz="0.0" iyy="0.001" iyz="0.0" izz="0.001"/>
    </inertial>
  </link>
  <link name="left_wrist_2_link">
    <visual>
      <origin rpy="0 0 0" xyz="0 0 0"/>
      <geometry>
        <mesh filename="package://boxbot_description/meshes/wrist_2_link.new.stl"/>
      </geometry>
      <material name="">
        <color rgba="0.15 0.15 0.15 1.0"/>
      </material>
    </visual>
    <collision>
      <origin rpy="0 0 0" xyz="0 0 0"/>
      <geometry>
        <mesh filename="package://boxbot_description/meshes/wrist_2_link.new.stl"/>
      </geometry>
    </collision>
    <inertial>
      <origin rpy="0 0 0" xyz="-0.018000 0.0 0.01500 "/>
      <mass value="6.3e-2"/>
      <inertia ixx="0.001" ixy="0.0" ixz="0.0" iyy="0.001" iyz="0.0" izz="0.001"/>
    </inertial>
  </link>
  <!-- joints -->
  <joint name="left_arm_base_joint" type="fixed">
    <origin rpy="-1.5707963268 0 0" xyz="0 0.087325 0.0635"/>
    <parent link="torso"/>
    <child link="left_arm_base_link"/>
  </joint>
  <joint name="left_joint_1" type="revolute">
    <origin rpy="0 0 0" xyz="0 0 0.065"/>
    <parent link="left_arm_base_link"/>
    <child link="left_shoulder_link"/>
    <axis xyz="0 0 1"/>
    <limit effort="6" lower="-2.617" upper="2.617" velocity="0.785"/>
  </joint>
  <joint name="left_joint_2" type="revolute">
    <!--origin xyz="0.04825 0 0.14203" rpy="0 0 0" /-->
    <origin rpy="0 0 0" xyz="0 0 0"/>
    <parent link="left_shoulder_link"/>
    <child link="left_biceps_link"/>
    <axis xyz="0 1 0"/>
    <limit effort="6" lower="-1.571" upper="1.571" velocity="1.571"/>
  </joint>
  <joint name="left_joint_3" type="revolute">
    <origin rpy="0 1.570795 0" xyz="0.04825 0 0.14203"/>
    <parent link="left_biceps_link"/>
    <child link="left_forearm_link"/>
    <axis xyz="0 1 0"/>
    <limit effort="6" lower="-1.571" upper="1.571" velocity="1.571"/>
  </joint>
  <joint name="left_joint_4" type="revolute">
    <origin rpy="0 0 0" xyz="0 0 0.14203"/>
    <parent link="left_forearm_link"/>
    <child link="left_wrist_1_link"/>
    <axis xyz="0 1 0"/>
    <limit effort="6" lower="-1.745" upper="1.745" velocity="1.571"/>
  </joint>
  <joint name="left_joint_5" type="revolute">
    <origin rpy="0 0 0" xyz="0 0 0.0715"/>
    <parent link="left_wrist_1_link"/>
    <child link="left_wrist_2_link"/>
    <axis xyz="0 0 1"/>
    <limit effort="6" lower="-2.617" upper="2.617" velocity="1.571"/>
  </joint>
  <link name="left_gripper_rail_link">
    <visual>
      <origin rpy="0 0 1.57" xyz="0 0 0"/>
      <geometry>
        <mesh filename="package://boxbot_description/meshes/gripper_rail_link.stl"/>
      </geometry>
      <material name="">
        <color rgba="0.15 0.15 0.15 1.0"/>
      </material>
    </visual>
    <!--Removed for now due to problems with collision in Gazebo-->
    <!--collision>
         <origin xyz="0 0 0" rpy="0 0 1.57" />
         <geometry>
            <mesh filename="package://boxbot_description/meshes/gripper_rail_link.stl"/>
         </geometry>
      </collision-->
    <inertial>
      <origin rpy="0 0 0" xyz="0 0 0"/>
      <mass value="7.0e-3"/>
      <inertia ixx="0.001" ixy="0.0" ixz="0.0" iyy="0.001" iyz="0.0" izz="0.001"/>
    </inertial>
  </link>
  <!--link name="${prefix}gripper_aux_link">
   </link-->
  <link name="left_gripper_1_link">
    <visual>
      <origin rpy="0 0 1.57" xyz="0 -0.0007 0"/>
      <geometry>
        <mesh filename="package://boxbot_description/meshes/gripper_hand_fixed_link.stl"/>
      </geometry>
      <material name="">
        <color rgba="0.15 0.15 0.15 1.0"/>
      </material>
    </visual>
    <collision>
      <origin rpy="0 0 1.57" xyz="0 -0.0007 0"/>
      <geometry>
        <mesh filename="package://boxbot_description/meshes/gripper_hand_fixed_link.stl"/>
      </geometry>
    </collision>
    <inertial>
      <origin rpy="0 0 0" xyz="0.0 -0.008292 0.017304"/>
      <mass value="8.0e-3"/>
      <inertia ixx="0.001" ixy="0.0" ixz="0.0" iyy="0.001" iyz="0.0" izz="0.001"/>
    </inertial>
  </link>
  <link name="left_gripper_2_link">
    <visual>
      <origin rpy="0 0 -1.57" xyz="0 0.0007 0"/>
      <geometry>
        <mesh filename="package://boxbot_description/meshes/gripper_hand_fixed_link.stl"/>
      </geometry>
      <material name="">
        <color rgba="0.15 0.15 0.15 1.0"/>
      </material>
    </visual>
    <collision>
      <origin rpy="0 0 -1.57" xyz="0 0.0007 0"/>
      <geometry>
        <mesh filename="package://boxbot_description/meshes/gripper_hand_fixed_link.stl"/>
      </geometry>
    </collision>
    <inertial>
      <origin rpy="0 0 0" xyz="0.0 0.008292 0.017304"/>
      <mass value="8.0e-3"/>
      <inertia ixx="0.001" ixy="0.0" ixz="0.0" iyy="0.001" iyz="0.0" izz="0.001"/>
    </inertial>
  </link>
  <joint name="left_joint_6" type="fixed">
    <origin rpy="0 0 0" xyz="0 0 0.043"/>
    <parent link="left_wrist_2_link"/>
    <child link="left_gripper_rail_link"/>
  </joint>
  <joint name="left_gripper_joint" type="prismatic">
    <origin rpy="0 0 0" xyz="0 0 0"/>
    <parent link="left_gripper_rail_link"/>
    <child link="left_gripper_1_link"/>
    <axis xyz="0 -1 0"/>
    <limit effort="0" lower="0.002" upper="0.031" velocity="0.5"/>
  </joint>
  <joint name="left_gripper_prismatic_joint_2" type="prismatic">
    <origin rpy="0 0 0" xyz="0 0 0"/>
    <parent link="left_gripper_rail_link"/>
    <child link="left_gripper_2_link"/>
    <mimic joint="left_gripper_joint"/>
    <axis xyz="0 1 0"/>
    <limit effort="0" lower="0.002" upper="0.031" velocity="0.5"/>
  </joint>
  <!-- links -->
  <link name="right_arm_base_link">
    <visual>
      <origin rpy="0 0 0" xyz="0 0 0"/>
      <geometry>
        <cylinder length="0.055" radius=".072"/>
      </geometry>
      <material name="">
        <color rgba="0.15 0.15 0.15 1.0"/>
      </material>
    </visual>
    <collision>
      <origin rpy="0 0 0" xyz="0 0 0"/>
      <geometry>
        <cylinder length="0.055" radius=".072"/>
      </geometry>
    </collision>
    <inertial>
      <origin rpy="0 0 0" xyz="0 0 0.0275"/>
      <mass value="1"/>
      <inertia ixx="1.0" ixy="0.0" ixz="0.0" iyy="1.0" iyz="0.0" izz="1.0"/>
    </inertial>
  </link>
  <link name="right_shoulder_link">
    <visual>
      <origin rpy="0 0 0" xyz="0 0 0"/>
      <geometry>
        <mesh filename="package://boxbot_description/meshes/shoulder_link.stl"/>
      </geometry>
      <material name="">
        <color rgba="0.15 0.15 0.15 1.0"/>
      </material>
    </visual>
    <collision>
      <origin rpy="0 0 0" xyz="0 0 0"/>
      <geometry>
        <mesh filename="package://boxbot_description/meshes/shoulder_link.stl"/>
      </geometry>
    </collision>
    <inertial>
      <origin rpy="0 0 0" xyz="0.0 0.0 -0.04"/>
      <mass value="0.061"/>
      <inertia ixx="0.001" ixy="0.0" ixz="0.0" iyy="0.001" iyz="0.0" izz="0.001"/>
    </inertial>
  </link>
  <link name="right_biceps_link">
    <visual>
      <origin rpy="0 0 0" xyz="0 0 0"/>
      <geometry>
        <mesh filename="package://boxbot_description/meshes/biceps_link.new.stl"/>
      </geometry>
      <material name="">
        <color rgba="0.15 0.15 0.15 1.0"/>
      </material>
    </visual>
    <collision>
      <origin rpy="0 0 0" xyz="0 0 0"/>
      <geometry>
        <mesh filename="package://boxbot_description/meshes/biceps_link.new.stl"/>
      </geometry>
    </collision>
    <inertial>
      <origin rpy="0 0 0" xyz="0.006670 0.0 0.083394"/>
      <mass value="3.62e-1"/>
      <inertia ixx="0.001" ixy="0.0" ixz="0.0" iyy="0.001" iyz="0.0" izz="0.001"/>
    </inertial>
  </link>
  <link name="right_forearm_link">
    <visual>
      <origin rpy="0 0 0" xyz="0 0 0"/>
      <geometry>
        <mesh filename="package://boxbot_description/meshes/forearm_link.new.stl"/>
      </geometry>
      <material name="">
        <color rgba="0.15 0.15 0.15 1.0"/>
      </material>
    </visual>
    <collision>
      <origin rpy="0 0 0" xyz="0 0 0"/>
      <geometry>
        <mesh filename="package://boxbot_description/meshes/forearm_link.new.stl"/>
      </geometry>
    </collision>
    <inertial>
      <origin rpy="0 0 0" xyz="0.000018 0.0 0.090995"/>
      <mass value="1.87e-1"/>
      <inertia ixx="0.001" ixy="0.0" ixz="0.0" iyy="0.001" iyz="0.0" izz="0.001"/>
    </inertial>
  </link>
  <link name="right_wrist_1_link">
    <visual>
      <origin rpy="0 0 0" xyz="0 0 0"/>
      <geometry>
        <mesh filename="package://boxbot_description/meshes/wrist_1_link.stl"/>
      </geometry>
      <material name="">
        <color rgba="0.15 0.15 0.15 1.0"/>
      </material>
    </visual>
    <collision>
      <origin rpy="0 0 0" xyz="0 0 0"/>
      <geometry>
        <mesh filename="package://boxbot_description/meshes/wrist_1_link.stl"/>
      </geometry>
    </collision>
    <inertial>
      <origin rpy="0 0 0" xyz="-0.010852 0.0 0.048078"/>
      <mass value="9.1e-2"/>
      <inertia ixx="0.001" ixy="0.0" ixz="0.0" iyy="0.001" iyz="0.0" izz="0.001"/>
    </inertial>
  </link>
  <link name="right_wrist_2_link">
    <visual>
      <origin rpy="0 0 0" xyz="0 0 0"/>
      <geometry>
        <mesh filename="package://boxbot_description/meshes/wrist_2_link.new.stl"/>
      </geometry>
      <material name="">
        <color rgba="0.15 0.15 0.15 1.0"/>
      </material>
    </visual>
    <collision>
      <origin rpy="0 0 0" xyz="0 0 0"/>
      <geometry>
        <mesh filename="package://boxbot_description/meshes/wrist_2_link.new.stl"/>
      </geometry>
    </collision>
    <inertial>
      <origin rpy="0 0 0" xyz="-0.018000 0.0 0.01500 "/>
      <mass value="6.3e-2"/>
      <inertia ixx="0.001" ixy="0.0" ixz="0.0" iyy="0.001" iyz="0.0" izz="0.001"/>
    </inertial>
  </link>
  <!-- joints -->
  <joint name="right_arm_base_joint" type="fixed">
    <origin rpy="1.5707963268 0 0" xyz="0 -0.087325 0.0635"/>
    <parent link="torso"/>
    <child link="right_arm_base_link"/>
  </joint>
  <joint name="right_joint_1" type="revolute">
    <origin rpy="0 0 0" xyz="0 0 0.065"/>
    <parent link="right_arm_base_link"/>
    <child link="right_shoulder_link"/>
    <axis xyz="0 0 1"/>
    <limit effort="6" lower="-2.617" upper="2.617" velocity="0.785"/>
  </joint>
  <joint name="right_joint_2" type="revolute">
    <!--origin xyz="0.04825 0 0.14203" rpy="0 0 0" /-->
    <origin rpy="0 0 0" xyz="0 0 0"/>
    <parent link="right_shoulder_link"/>
    <child link="right_biceps_link"/>
    <axis xyz="0 1 0"/>
    <limit effort="6" lower="-1.571" upper="1.571" velocity="1.571"/>
  </joint>
  <joint name="right_joint_3" type="revolute">
    <origin rpy="0 1.570795 0" xyz="0.04825 0 0.14203"/>
    <parent link="right_biceps_link"/>
    <child link="right_forearm_link"/>
    <axis xyz="0 1 0"/>
    <limit effort="6" lower="-1.571" upper="1.571" velocity="1.571"/>
  </joint>
  <joint name="right_joint_4" type="revolute">
    <origin rpy="0 0 0" xyz="0 0 0.14203"/>
    <parent link="right_forearm_link"/>
    <child link="right_wrist_1_link"/>
    <axis xyz="0 1 0"/>
    <limit effort="6" lower="-1.745" upper="1.745" velocity="1.571"/>
  </joint>
  <joint name="right_joint_5" type="revolute">
    <origin rpy="0 0 0" xyz="0 0 0.0715"/>
    <parent link="right_wrist_1_link"/>
    <child link="right_wrist_2_link"/>
    <axis xyz="0 0 1"/>
    <limit effort="6" lower="-2.617" upper="2.617" velocity="1.571"/>
  </joint>
  <link name="right_gripper_rail_link">
    <visual>
      <origin rpy="0 0 1.57" xyz="0 0 0"/>
      <geometry>
        <mesh filename="package://boxbot_description/meshes/gripper_rail_link.stl"/>
      </geometry>
      <material name="">
        <color rgba="0.15 0.15 0.15 1.0"/>
      </material>
    </visual>
    <!--Removed for now due to problems with collision in Gazebo-->
    <!--collision>
         <origin xyz="0 0 0" rpy="0 0 1.57" />
         <geometry>
            <mesh filename="package://boxbot_description/meshes/gripper_rail_link.stl"/>
         </geometry>
      </collision-->
    <inertial>
      <origin rpy="0 0 0" xyz="0 0 0"/>
      <mass value="7.0e-3"/>
      <inertia ixx="0.001" ixy="0.0" ixz="0.0" iyy="0.001" iyz="0.0" izz="0.001"/>
    </inertial>
  </link>
  <!--link name="${prefix}gripper_aux_link">
   </link-->
  <link name="right_gripper_1_link">
    <visual>
      <origin rpy="0 0 1.57" xyz="0 -0.0007 0"/>
      <geometry>
        <mesh filename="package://boxbot_description/meshes/gripper_hand_fixed_link.stl"/>
      </geometry>
      <material name="">
        <color rgba="0.15 0.15 0.15 1.0"/>
      </material>
    </visual>
    <collision>
      <origin rpy="0 0 1.57" xyz="0 -0.0007 0"/>
      <geometry>
        <mesh filename="package://boxbot_description/meshes/gripper_hand_fixed_link.stl"/>
      </geometry>
    </collision>
    <inertial>
      <origin rpy="0 0 0" xyz="0.0 -0.008292 0.017304"/>
      <mass value="8.0e-3"/>
      <inertia ixx="0.001" ixy="0.0" ixz="0.0" iyy="0.001" iyz="0.0" izz="0.001"/>
    </inertial>
  </link>
  <link name="right_gripper_2_link">
    <visual>
      <origin rpy="0 0 -1.57" xyz="0 0.0007 0"/>
      <geometry>
        <mesh filename="package://boxbot_description/meshes/gripper_hand_fixed_link.stl"/>
      </geometry>
      <material name="">
        <color rgba="0.15 0.15 0.15 1.0"/>
      </material>
    </visual>
    <collision>
      <origin rpy="0 0 -1.57" xyz="0 0.0007 0"/>
      <geometry>
        <mesh filename="package://boxbot_description/meshes/gripper_hand_fixed_link.stl"/>
      </geometry>
    </collision>
    <inertial>
      <origin rpy="0 0 0" xyz="0.0 0.008292 0.017304"/>
      <mass value="8.0e-3"/>
      <inertia ixx="0.001" ixy="0.0" ixz="0.0" iyy="0.001" iyz="0.0" izz="0.001"/>
    </inertial>
  </link>
  <joint name="right_joint_6" type="fixed">
    <origin rpy="0 0 0" xyz="0 0 0.043"/>
    <parent link="right_wrist_2_link"/>
    <child link="right_gripper_rail_link"/>
  </joint>
  <joint name="right_gripper_joint" type="prismatic">
    <origin rpy="0 0 0" xyz="0 0 0"/>
    <parent link="right_gripper_rail_link"/>
    <child link="right_gripper_1_link"/>
    <axis xyz="0 -1 0"/>
    <limit effort="0" lower="0.002" upper="0.031" velocity="0.5"/>
  </joint>
  <joint name="right_gripper_prismatic_joint_2" type="prismatic">
    <origin rpy="0 0 0" xyz="0 0 0"/>
    <parent link="right_gripper_rail_link"/>
    <child link="right_gripper_2_link"/>
    <mimic joint="right_gripper_joint"/>
    <axis xyz="0 1 0"/>
    <limit effort="0" lower="0.002" upper="0.031" velocity="0.5"/>
  </joint>
  <!--gazebo ros control-->
  <gazebo>
    <plugin filename="libgazebo_ros_control.so" name="gazebo_ros_control">
      <robotNamespace>/boxbot</robotNamespace>
    </plugin>
  </gazebo>
  <!--transmissions-->
  <!--left-->
  <transmission name="ltran1">
    <type>transmission_interface/SimpleTransmission</type>
    <joint name="left_joint_1">
      <hardwareInterface>hardware_interface/PositionJointInterface</hardwareInterface>
    </joint>
    <actuator name="left_motor1">
      <hardwareInterface>hardware_interface/PositionJointInterface</hardwareInterface>
      <mechanicalReduction>1</mechanicalReduction>
    </actuator>
  </transmission>
  <transmission name="ltran2">
    <type>transmission_interface/SimpleTransmission</type>
    <joint name="left_joint_2">
      <hardwareInterface>hardware_interface/PositionJointInterface</hardwareInterface>
    </joint>
    <actuator name="left_motor2">
      <hardwareInterface>hardware_interface/PositionJointInterface</hardwareInterface>
      <mechanicalReduction>1</mechanicalReduction>
    </actuator>
  </transmission>
  <transmission name="ltran3">
    <type>transmission_interface/SimpleTransmission</type>
    <joint name="left_joint_3">
      <hardwareInterface>hardware_interface/PositionJointInterface</hardwareInterface>
    </joint>
    <actuator name="left_motor3">
      <hardwareInterface>hardware_interface/PositionJointInterface</hardwareInterface>
      <mechanicalReduction>1</mechanicalReduction>
    </actuator>
  </transmission>
  <transmission name="ltran4">
    <type>transmission_interface/SimpleTransmission</type>
    <joint name="left_joint_4">
      <hardwareInterface>hardware_interface/PositionJointInterface</hardwareInterface>
    </joint>
    <actuator name="left_motor4">
      <hardwareInterface>hardware_interface/PositionJointInterface</hardwareInterface>
      <mechanicalReduction>1</mechanicalReduction>
    </actuator>
  </transmission>
  <transmission name="ltran5">
    <type>transmission_interface/SimpleTransmission</type>
    <joint name="left_joint_5">
      <hardwareInterface>hardware_interface/PositionJointInterface</hardwareInterface>
    </joint>
    <actuator name="left_motor5">
      <hardwareInterface>hardware_interface/PositionJointInterface</hardwareInterface>
      <mechanicalReduction>1</mechanicalReduction>
    </actuator>
  </transmission>
  <transmission name="ltran6">
    <type>transmission_interface/SimpleTransmission</type>
    <joint name="left_gripper_joint">
      <hardwareInterface>hardware_interface/PositionJointInterface</hardwareInterface>
    </joint>
    <actuator name="left_motor6">
      <hardwareInterface>hardware_interface/PositionJointInterface</hardwareInterface>
      <mechanicalReduction>1</mechanicalReduction>
    </actuator>
  </transmission>
  <transmission name="ltran7">
    <type>transmission_interface/SimpleTransmission</type>
    <joint name="left_gripper_prismatic_joint_2">
      <hardwareInterface>hardware_interface/PositionJointInterface</hardwareInterface>
    </joint>
    <actuator name="left_motor7">
      <hardwareInterface>hardware_interface/PositionJointInterface</hardwareInterface>
      <mechanicalReduction>1</mechanicalReduction>
    </actuator>
  </transmission>
  <!--right-->
  <transmission name="rtran1">
    <type>transmission_interface/SimpleTransmission</type>
    <joint name="right_joint_1">
      <hardwareInterface>hardware_interface/PositionJointInterface</hardwareInterface>
    </joint>
    <actuator name="right_motor1">
      <hardwareInterface>hardware_interface/PositionJointInterface</hardwareInterface>
      <mechanicalReduction>1</mechanicalReduction>
    </actuator>
  </transmission>
  <transmission name="rtran2">
    <type>transmission_interface/SimpleTransmission</type>
    <joint name="right_joint_2">
      <hardwareInterface>hardware_interface/PositionJointInterface</hardwareInterface>
    </joint>
    <actuator name="right_motor2">
      <hardwareInterface>hardware_interface/PositionJointInterface</hardwareInterface>
      <mechanicalReduction>1</mechanicalReduction>
    </actuator>
  </transmission>
  <transmission name="rtran3">
    <type>transmission_interface/SimpleTransmission</type>
    <joint name="right_joint_3">
      <hardwareInterface>hardware_interface/PositionJointInterface</hardwareInterface>
    </joint>
    <actuator name="right_motor3">
      <hardwareInterface>hardware_interface/PositionJointInterface</hardwareInterface>
      <mechanicalReduction>1</mechanicalReduction>
    </actuator>
  </transmission>
  <transmission name="rtran4">
    <type>transmission_interface/SimpleTransmission</type>
    <joint name="right_joint_4">
      <hardwareInterface>hardware_interface/PositionJointInterface</hardwareInterface>
    </joint>
    <actuator name="right_motor4">
      <hardwareInterface>hardware_interface/PositionJointInterface</hardwareInterface>
      <mechanicalReduction>1</mechanicalReduction>
    </actuator>
  </transmission>
  <transmission name="rtran5">
    <type>transmission_interface/SimpleTransmission</type>
    <joint name="right_joint_5">
      <hardwareInterface>hardware_interface/PositionJointInterface</hardwareInterface>
    </joint>
    <actuator name="right_motor5">
      <hardwareInterface>hardware_interface/PositionJointInterface</hardwareInterface>
      <mechanicalReduction>1</mechanicalReduction>
    </actuator>
  </transmission>
  <transmission name="rtran6">
    <type>transmission_interface/SimpleTransmission</type>
    <joint name="right_gripper_joint">
      <hardwareInterface>hardware_interface/PositionJointInterface</hardwareInterface>
    </joint>
    <actuator name="right_motor6">
      <hardwareInterface>hardware_interface/PositionJointInterface</hardwareInterface>
      <mechanicalReduction>1</mechanicalReduction>
    </actuator>
  </transmission>
  <transmission name="rtran7">
    <type>transmission_interface/SimpleTransmission</type>
    <joint name="right_gripper_prismatic_joint_2">
      <hardwareInterface>hardware_interface/PositionJointInterface</hardwareInterface>
    </joint>
    <actuator name="right_motor7">
      <hardwareInterface>hardware_interface/PositionJointInterface</hardwareInterface>
      <mechanicalReduction>1</mechanicalReduction>
    </actuator>
  </transmission>
  <!--Gazebo compatable colors-->
  <gazebo reference="base_link">
    <mu1>0.3</mu1>
    <mu2>0.3</mu2>
    <material>Gazebo/Wood</material>
  </gazebo>
  <gazebo reference="torso">
    <mu1>0.3</mu1>
    <mu2>0.3</mu2>
    <material>Gazebo/Wood</material>
  </gazebo>
  <!--left arm-->
  <gazebo reference="left_arm_base_link">
    <mu1>0.3</mu1>
    <mu2>0.3</mu2>
    <material>Gazebo/DarkGrey</material>
  </gazebo>
  <gazebo reference="left_shoulder_link">
    <mu1>0.3</mu1>
    <mu2>0.3</mu2>
    <material>Gazebo/DarkGrey</material>
  </gazebo>
  <gazebo reference="left_biceps_link">
    <mu1>0.3</mu1>
    <mu2>0.3</mu2>
    <material>Gazebo/DarkGrey</material>
  </gazebo>
  <gazebo reference="left_forearm_link">
    <mu1>0.3</mu1>
    <mu2>0.3</mu2>
    <material>Gazebo/DarkGrey</material>
  </gazebo>
  <gazebo reference="left_wrist_1_link">
    <mu1>0.3</mu1>
    <mu2>0.3</mu2>
    <material>Gazebo/DarkGrey</material>
  </gazebo>
  <gazebo reference="left_wrist_2_link">
    <mu1>0.3</mu1>
    <mu2>0.3</mu2>
    <material>Gazebo/DarkGrey</material>
  </gazebo>
  <gazebo reference="left_gripper_rail_link">
    <mu1>0.3</mu1>
    <mu2>0.3</mu2>
    <material>Gazebo/DarkGrey</material>
  </gazebo>
  <gazebo reference="left_gripper_1_link">
    <mu1>1.0</mu1>
    <mu2>1.0</mu2>
    <material>Gazebo/DarkGrey</material>
  </gazebo>
  <gazebo reference="left_gripper_2_link">
    <mu1>1.0</mu1>
    <mu2>1.0</mu2>
    <material>Gazebo/DarkGrey</material>
  </gazebo>
  <!--right arm-->
  <gazebo reference="right_arm_base_link">
    <mu1>0.3</mu1>
    <mu2>0.3</mu2>
    <material>Gazebo/DarkGrey</material>
  </gazebo>
  <gazebo reference="right_shoulder_link">
    <mu1>0.3</mu1>
    <mu2>0.3</mu2>
    <material>Gazebo/DarkGrey</material>
  </gazebo>
  <gazebo reference="right_biceps_link">
    <mu1>0.3</mu1>
    <mu2>0.3</mu2>
    <material>Gazebo/DarkGrey</material>
  </gazebo>
  <gazebo reference="right_forearm_link">
    <mu1>0.3</mu1>
    <mu2>0.3</mu2>
    <material>Gazebo/DarkGrey</material>
  </gazebo>
  <gazebo reference="right_wrist_1_link">
    <mu1>0.3</mu1>
    <mu2>0.3</mu2>
    <material>Gazebo/DarkGrey</material>
  </gazebo>
  <gazebo reference="right_wrist_2_link">
    <mu1>0.3</mu1>
    <mu2>0.3</mu2>
    <material>Gazebo/DarkGrey</material>
  </gazebo>
  <gazebo reference="right_gripper_rail_link">
    <mu1>0.3</mu1>
    <mu2>0.3</mu2>
    <material>Gazebo/DarkGrey</material>
  </gazebo>
  <gazebo reference="right_gripper_1_link">
    <mu1>1.0</mu1>
    <mu2>1.0</mu2>
    <material>Gazebo/DarkGrey</material>
  </gazebo>
  <gazebo reference="right_gripper_2_link">
    <mu1>1.0</mu1>
    <mu2>1.0</mu2>
    <material>Gazebo/DarkGrey</material>
  </gazebo>
</robot>
