<?xml version="1.0" encoding="utf-8"?>
<!-- =================================================================================== -->
<!-- |    This document was autogenerated by xacro from boxbot_2.urdf.xacro            | -->
<!-- |    EDITING THIS FILE BY HAND IS NOT RECOMMENDED                                 | -->
<!-- =================================================================================== -->
<robot name="boxbot">
  <link name="world"/>
  <link name="torso">
    <visual>
      <geometry>
        <mesh filename="package://boxbot_description/meshes/torso.stl"/>
      </geometry>
      <material name="">
        <color rgba="0.96 0.76 0.13 1.0"/>
      </material>
    </visual>
    <collision>
      <origin rpy="0 0 0" xyz="0 0 0"/>
      <geometry>
        <mesh filename="package://boxbot_description/meshes/torso.stl"/>
      </geometry>
    </collision>
    <inertial>
      <!--placeholders-->
      <origin rpy="0 0 0" xyz="0.0 0.0 0.0"/>
      <mass value="1"/>
      <inertia ixx="1.0" ixy="0.0" ixz="0.0" iyy="1.0" iyz="0.0" izz="1.0"/>
    </inertial>
  </link>
  <joint name="fixed" type="fixed">
    <origin rpy="0 0 0" xyz="0 0 0.009525"/>
    <parent link="world"/>
    <child link="torso"/>
  </joint>
  <!-- links -->
  <link name="left_shoulder_link">
    <visual>
      <origin rpy="0 0 0" xyz="0 0 0"/>
      <geometry>
        <mesh filename="package://boxbot_description/meshes/shoulder_link.stl"/>
      </geometry>
      <material name="">
        <color rgba="0.15 0.15 0.15 1.0"/>
      </material>
    </visual>
    <collision>
      <origin rpy="0 0 0" xyz="0 0 0"/>
      <geometry>
        <mesh filename="package://boxbot_description/meshes/shoulder_link.stl"/>
      </geometry>
    </collision>
    <inertial>
      <origin rpy="0 0 0" xyz="0.0 0.0 -0.04"/>
      <mass value="0.061"/>
      <inertia ixx="0.001" ixy="0.0" ixz="0.0" iyy="0.001" iyz="0.0" izz="0.001"/>
    </inertial>
  </link>
  <link name="left_biceps_link">
    <visual>
      <origin rpy="0 0 0" xyz="0 0 0"/>
      <geometry>
        <mesh filename="package://boxbot_description/meshes/biceps_link.new.stl"/>
      </geometry>
      <material name="">
        <color rgba="0.15 0.15 0.15 1.0"/>
      </material>
    </visual>
    <collision>
      <origin rpy="0 0 0" xyz="0 0 0"/>
      <geometry>
        <mesh filename="package://boxbot_description/meshes/biceps_link.new.stl"/>
      </geometry>
    </collision>
    <inertial>
      <origin rpy="0 0 0" xyz="0.006670 0.0 0.083394"/>
      <mass value="3.62e-1"/>
      <inertia ixx="0.001" ixy="0.0" ixz="0.0" iyy="0.001" iyz="0.0" izz="0.001"/>
    </inertial>
  </link>
  <link name="left_forearm_1_link">
    <visual>
      <origin rpy="0 0 0" xyz="0 0 0"/>
      <geometry>
        <mesh filename="package://boxbot_description/meshes/forearm_1_link.stl"/>
      </geometry>
      <material name="">
        <color rgba="0.15 0.15 0.15 1.0"/>
      </material>
    </visual>
    <collision>
      <origin rpy="0 0 0" xyz="0 0 0"/>
      <geometry>
        <mesh filename="package://boxbot_description/meshes/forearm_1_link.stl"/>
      </geometry>
    </collision>
    <inertial>
      <origin rpy="0 0 0" xyz="0.000018 0.0 0.090995"/>
      <mass value="1.87e-1"/>
      <inertia ixx="0.001" ixy="0.0" ixz="0.0" iyy="0.001" iyz="0.0" izz="0.001"/>
    </inertial>
  </link>
  <link name="left_forearm_2_link">
    <visual>
      <origin rpy="0 0 0" xyz="0 0 0"/>
      <geometry>
        <mesh filename="package://boxbot_description/meshes/forearm_2_link.stl"/>
      </geometry>
      <material name="">
        <color rgba="0.15 0.15 0.15 1.0"/>
      </material>
    </visual>
    <collision>
      <origin rpy="0 0 0" xyz="0 0 0"/>
      <geometry>
        <mesh filename="package://boxbot_description/meshes/forearm_2_link.stl"/>
      </geometry>
    </collision>
    <inertial>
      <origin rpy="0 0 0" xyz="0.000018 0.0 0.090995"/>
      <mass value="1.87e-1"/>
      <inertia ixx="0.001" ixy="0.0" ixz="0.0" iyy="0.001" iyz="0.0" izz="0.001"/>
    </inertial>
  </link>
  <link name="left_wrist_1_link">
    <visual>
      <origin rpy="0 0 0" xyz="0 0 0"/>
      <geometry>
        <mesh filename="package://boxbot_description/meshes/wrist_1_link.stl"/>
      </geometry>
      <material name="">
        <color rgba="0.15 0.15 0.15 1.0"/>
      </material>
    </visual>
    <collision>
      <origin rpy="0 0 0" xyz="0 0 0"/>
      <geometry>
        <mesh filename="package://boxbot_description/meshes/wrist_1_link.stl"/>
      </geometry>
    </collision>
    <inertial>
      <origin rpy="0 0 0" xyz="-0.010852 0.0 0.048078"/>
      <mass value="9.1e-2"/>
      <inertia ixx="0.001" ixy="0.0" ixz="0.0" iyy="0.001" iyz="0.0" izz="0.001"/>
    </inertial>
  </link>
  <link name="left_wrist_2_link">
    <visual>
      <origin rpy="0 0 0" xyz="0 0 0"/>
      <geometry>
        <mesh filename="package://boxbot_description/meshes/wrist_2_link.new.stl"/>
      </geometry>
      <material name="">
        <color rgba="0.15 0.15 0.15 1.0"/>
      </material>
    </visual>
    <collision>
      <origin rpy="0 0 0" xyz="0 0 0"/>
      <geometry>
        <mesh filename="package://boxbot_description/meshes/wrist_2_link.new.stl"/>
      </geometry>
    </collision>
    <inertial>
      <origin rpy="0 0 0" xyz="-0.018000 0.0 0.01500 "/>
      <mass value="6.3e-2"/>
      <inertia ixx="0.001" ixy="0.0" ixz="0.0" iyy="0.001" iyz="0.0" izz="0.001"/>
    </inertial>
  </link>
  <!-- joints -->
  <joint name="left_shoulder_joint_1" type="revolute">
    <origin rpy="0 0 0" xyz="0.099613 0 0.243180"/>
    <parent link="torso"/>
    <child link="left_shoulder_link"/>
    <axis xyz="0 0 1"/>
    <limit effort="6" lower="-2.617" upper="2.617" velocity="0.785"/>
  </joint>
  <!--joint name="${prefix}shoulder_joint_2" type="revolute">
         <!origin xyz="0 0 0" rpy="0 0 0" />
         <parent link="${prefix}shoulder_link" />
         <child link="${prefix}biceps_link" />
         <!axis xyz="0 1 0" />
         <!limit lower="-1.571" upper="1.571" effort="6" velocity="1.571" />
      </joint>

      <joint name="${prefix}_elbow_joint" type="revolute">
         <!origin xyz="${M_SCALE*48.25} 0 ${M_SCALE*142.03}" rpy="0 ${M_PI/2.0} 0" />
         <parent link="${prefix}biceps_link" />
         <child link="${prefix}forearm_1_link" />
         <!axis xyz="0 1 0" />
         <!limit lower="-1.571" upper="1.571" effort="6" velocity="1.571" />
      </joint>

      <joint name="${prefix}wrist_joint_1" type="revolute">
         <!origin xyz="0 0 ${M_SCALE*142.03}" rpy="0 0 0" />
         <parent link="${prefix}forearm_1_link" />
         <child link="${prefix}forearm_2_link" />
         <!axis xyz="0 1 0" />
         <!limit lower="-1.745" upper="1.745" effort="6" velocity="1.571" />
      </joint>

      <joint name="${prefix}wrist_joint_2" type="revolute">
         <!origin xyz="0 0 ${M_SCALE*71.5}" rpy="0 0 0" />
         <parent link="${prefix}forearm_2_link" />
         <child link="${prefix}wrist_1_link" />
         <!axis xyz="0 0 1" />
         <!limit lower="-2.617" upper="2.617" effort="6" velocity="1.571" />
      </joint>

      <joint name="${prefix}wrist_joint_3" type="revolute">
         <!origin xyz="0 0 ${M_SCALE*71.5}" rpy="0 0 0" />
         <parent link="${prefix}wrist_1_link" />
         <child link="${prefix}wrist_2_link" />
         <!axis xyz="0 0 1" />
         <!limit lower="-2.617" upper="2.617" effort="6" velocity="1.571" />
      </joint-->
  <!-- gripper -->
  <!--xacro:include filename="$(find boxbot_description)/urdf/widowx_gripper.xacro"/-->
  <!--xacro:include filename="$(find boxbot_description)/urdf/widowx_6dof.urdf.xacro"/>
  <xacro:widowx_arm parent="torso" prefix="right_">
    <origin xyz="0 -0.087325 0.0635" rpy="1.5707963268 0 0"/>
  </xacro:widowx_arm>

  <xacro:include filename="$(find boxbot_description)/urdf/servos.urdf.xacro"/>
  <xacro:include filename="$(find boxbot_description)/urdf/materials.gazebo"/-->
</robot>
